{"uuid": "6afea872-9c08-4f46-be1d-6646f2b16b05", "children": ["2bf88bd7-a06b-41b8-a202-fed0ae75ceeb"], "befores": [{"name": "prepara_env", "status": "broken", "statusDetails": {"message": "selenium.common.exceptions.TimeoutException: Message: timeout\n  (Session info: chrome=71.0.3578.98)\n  (Driver info: chromedriver=2.46.628402 (536cd7adbad73a3783fdc2cab92ab2ba7ec361e1),platform=Windows NT 6.1.7601 SP1 x86_64)\n\n", "trace": "  File \"D:\\Python37\\lib\\site-packages\\pluggy\\callers.py\", line 187, in _multicall\n    res = hook_impl.function(*args)\n  File \"D:\\Python37\\lib\\site-packages\\_pytest\\fixtures.py\", line 937, in pytest_fixture_setup\n    result = call_fixture_func(fixturefunc, request, kwargs)\n  File \"D:\\Python37\\lib\\site-packages\\_pytest\\fixtures.py\", line 790, in call_fixture_func\n    res = next(it)\n  File \"I:\\PycharmProjects\\InternetThingsplatform\\TestCase\\conftest.py\", line 31, in prepara_env\n    driver.get(cd.login_url)\n  File \"D:\\Python37\\lib\\site-packages\\selenium\\webdriver\\remote\\webdriver.py\", line 333, in get\n    self.execute(Command.GET, {'url': url})\n  File \"D:\\Python37\\lib\\site-packages\\selenium\\webdriver\\remote\\webdriver.py\", line 321, in execute\n    self.error_handler.check_response(response)\n  File \"D:\\Python37\\lib\\site-packages\\selenium\\webdriver\\remote\\errorhandler.py\", line 242, in check_response\n    raise exception_class(message, screen, stacktrace)\n"}, "start": 1558343760846, "stop": 1558344064248}], "start": 1558343760846, "stop": 1558344064433}