{"name": "test_failed", "status": "failed", "statusDetails": {"message": "AssertionError: assert 1 != 1", "trace": "self = <TestCase.test_0_login.TestLogin object at 0x0000000003F93A20>\n\n    def test_failed(self):\n>       assert  1!=1\nE       assert 1 != 1\n\nTestCase\\test_0_login.py:38: AssertionError"}, "start": 1560320504500, "stop": 1560320504500, "uuid": "f6807426-88cc-4e95-b965-88b221076186", "historyId": "98d4ab842603cdfc0380ae0bd8991cba", "fullName": "TestCase.test_0_login.TestLogin#test_failed", "labels": [{"name": "tag", "value": "login"}, {"name": "parentSuite", "value": "TestCase"}, {"name": "suite", "value": "test_0_login"}, {"name": "subSuite", "value": "TestLogin"}, {"name": "host", "value": "bj_jd-PC"}, {"name": "thread", "value": "10352-MainThread"}, {"name": "framework", "value": "pytest"}, {"name": "language", "value": "cpython3"}, {"name": "package", "value": "TestCase.test_0_login"}]}